Исключения — это механизм обработки ошибок, который позволяет программе реагировать на неожиданные ситуации и ошибки во время выполнения. Обработка исключений в C++ помогает избежать аварийного завершения программы и позволяет разработчику грамотно управлять ошибками, направляя выполнение программы в безопасное русло. Правильная обработка исключений обеспечивает стабильную работу программы и предотвращает утечки ресурсов.

## Содержание

1. [Что такое исключение](#1.%20Что%20такое%20исключение)
2. [Основные конструкции для обработки исключений](#2.%20Основные%20конструкции%20для%20обработки%20исключений)
3. [Использование RAII для управления ресурсами](#3.%20Использование%20RAII%20для%20управления%20ресурсами)
4. [Создание пользовательских исключений](#4.%20Создание%20пользовательских%20исключений)
5. [Примеры обработки исключений](#5.%20Примеры%20обработки%20исключений)
6. [Рекомендации по обработке исключений](#6.%20Рекомендации%20по%20обработке%20исключений)

---

## 1. Что такое исключение

**Исключение** — это механизм, который позволяет программе "выбросить" ошибку (исключение) и "поймать" её в другом месте программы для корректной обработки. Исключение возникает, когда программа сталкивается с неразрешимой ситуацией, например, делением на ноль, выходом за пределы массива или ошибкой ввода/вывода.

В C++ исключения выбрасываются с помощью ключевого слова `throw` и перехватываются конструкцией `try-catch`.

Пример:

```cpp
int divide(int a, int b) {
    if (b == 0) {
        throw std::runtime_error("Division by zero");  // Выбрасываем исключение
    }
    return a / b;
}
```

---

## 2. Основные конструкции для обработки исключений

### `try`, `throw` и `catch`

- **try**: блок, в котором выполняется код, который может вызвать исключение.
- **throw**: команда для выброса исключения. Выбрасываемое исключение может быть объектом любого типа.
- **catch**: блок, который перехватывает и обрабатывает исключение.

Пример использования:

```cpp
#include <iostream>
#include <stdexcept>

int divide(int a, int b) {
    if (b == 0) {
        throw std::runtime_error("Division by zero");
    }
    return a / b;
}

int main() {
    try {
        int result = divide(10, 0);
        std::cout << "Result: " << result << std::endl;
    } catch (const std::runtime_error& e) {
        std::cerr << "Caught exception: " << e.what() << std::endl;
    }
    return 0;
}
```

### Множественные блоки `catch`

Можно использовать несколько блоков `catch`, чтобы перехватывать разные типы исключений.

```cpp
try {
    // Возможный источник исключения
} catch (const std::invalid_argument& e) {
    std::cerr << "Invalid argument: " << e.what() << std::endl;
} catch (const std::runtime_error& e) {
    std::cerr << "Runtime error: " << e.what() << std::endl;
}
```

### `catch (...)`

Чтобы поймать исключение любого типа, используется блок `catch (...)`. Это часто применяется для общей обработки ошибок, но рекомендуется использовать с осторожностью, так как может скрыть важные детали исключения.

```cpp
try {
    // Возможный источник исключения
} catch (...) {
    std::cerr << "Caught an unknown exception" << std::endl;
}
```

---

## 3. Использование RAII для управления ресурсами

**RAII (Resource Acquisition Is Initialization)** — это идиома C++, при которой захват ресурса (например, памяти или файлового дескриптора) происходит в конструкторе объекта, а освобождение — в деструкторе. Это особенно важно при обработке исключений, чтобы избежать утечек ресурсов.

Пример с использованием класса, управляющего файлом:

```cpp
#include <iostream>
#include <fstream>
#include <stdexcept>

class FileHandler {
public:
    FileHandler(const std::string& filename) {
        file.open(filename);
        if (!file.is_open()) {
            throw std::runtime_error("Failed to open file");
        }
    }

    ~FileHandler() {
        if (file.is_open()) {
            file.close();
        }
    }

    void write(const std::string& data) {
        if (file.is_open()) {
            file << data;
        }
    }

private:
    std::ofstream file;
};

int main() {
    try {
        FileHandler fileHandler("example.txt");
        fileHandler.write("Hello, world!");
    } catch (const std::runtime_error& e) {
        std::cerr << "Error: " << e.what() << std::endl;
    }
    return 0;
}
```

Здесь класс `FileHandler` гарантирует, что файл будет закрыт в деструкторе, даже если в программе возникнет исключение.

---

## 4. Создание пользовательских исключений

В C++ можно создавать свои собственные классы исключений, наследуя их от стандартных классов (например, `std::exception` или `std::runtime_error`).

Пример создания пользовательского исключения:

```cpp
#include <iostream>
#include <stdexcept>

class CustomException : public std::runtime_error {
public:
    CustomException(const std::string& message) : std::runtime_error(message) {}
};

int main() {
    try {
        throw CustomException("Custom exception occurred");
    } catch (const CustomException& e) {
        std::cerr << "Caught custom exception: " << e.what() << std::endl;
    }
    return 0;
}
```

---

## 5. Примеры обработки исключений

### Пример с математической ошибкой:

```cpp
#include <iostream>
#include <stdexcept>

int divide(int a, int b) {
    if (b == 0) {
        throw std::invalid_argument("Division by zero");
    }
    return a / b;
}

int main() {
    try {
        std::cout << "Result: " << divide(10, 0) << std::endl;
    } catch (const std::invalid_argument& e) {
        std::cerr << "Error: " << e.what() << std::endl;
    }
    return 0;
}
```

### Пример с ошибкой при работе с файлами:

```cpp
#include <iostream>
#include <fstream>
#include <stdexcept>

void openFile(const std::string& filename) {
    std::ifstream file(filename);
    if (!file.is_open()) {
        throw std::runtime_error("Failed to open file");
    }
    // Чтение файла
    file.close();
}

int main() {
    try {
        openFile("nonexistent.txt");
    } catch (const std::runtime_error& e) {
        std::cerr << "File error: " << e.what() << std::endl;
    }
    return 0;
}
```

---

## 6. Рекомендации по обработке исключений

1. **Не используйте исключения для управления потоком программы**: Исключения предназначены для обработки ошибок, а не для управления обычным потоком программы. Использование исключений для обычного управления потоком может сделать код сложным для понимания и сопровождения.

2. **Освобождение ресурсов в случае исключений**: Обязательно освобождайте ресурсы (память, файловые дескрипторы и т. д.) в случае исключений. Для этого рекомендуется использовать RAII.

3. **Перехват исключений по ссылке**: Всегда перехватывайте исключения по ссылке (`catch (const std::exception& e)`), чтобы избежать копирования объектов исключений и сохранить их полиморфизм.

4. **Не ловите исключения "на всякий случай"**: Не используйте блоки `catch (...)` без необходимости. Они могут скрыть истинную причину ошибки и усложнить отладку.

5. **Создавайте информативные сообщения об ошибках**: Исключения должны предоставлять ясную и полезную информацию о причине ошибки, чтобы её было легче диагностировать и исправлять.

---

## Заключение

Исключения — это мощный механизм для обработки ошибок, который помогает разработчику избегать аварийных завершений программы и обрабатывать ошибки на высоком уровне. Правильное использование исключений, в сочетании с техниками управления ресурсами, такими как RAII, делает программы более устойчивыми и легко сопровождаемыми.